<?xml version='1.0'?>

<sdf version='1.7'>
  <model name="soccer_ball">
    <static>false</static>
    <link name="ball_link">
      <inertial>
        <mass>0.22</mass>
        <inertia>
          <ixx>3.72e-4</ixx>
          <ixy>0</ixy>
          <ixz>0</ixz>
          <iyy>3.72e-4</iyy>
          <iyz>0</iyz>
          <izz>3.72e-4</izz>
        </inertia>
      </inertial>
      <collision name="soccer_ball_collision">
        <geometry>
          <sphere>
            <radius>0.065</radius>
          </sphere>
        </geometry>
        <surface>
          <bounce>
            <restitution_coefficient>0.7</restitution_coefficient>
            <threshold>0.01</threshold>
          </bounce>
          <friction>
            <ode>
              <mu>0.1</mu>
              <mu2>0.04</mu2>
            </ode>
          </friction>
          <contact>
            <ode>
              <max_vel>10</max_vel>
              <min_depth>0.01</min_depth>
            </ode>
          </contact>
        </surface>
      </collision>
      
      <visual name='visual'>
        <pose>0 0 0 0 0 0</pose>
        <geometry>
          <sphere>
            <!--radius>0.0327</radius-->
            <radius>0.065</radius>
          </sphere>
        </geometry>
        <material>
          <lighting>1</lighting>
          <!--script>
            <uri>file://media/materials/scripts/gazebo.material</uri>
            <name>Gazebo/Green</name>
          </script-->

          <script>
            <uri>file://media/materials/scripts/gazebo.material</uri>
            <name>Gazebo/CoM</name>
          </script>

          <shader type='pixel'>
            <normal_map>__default__</normal_map>
          </shader>
          <ambient>0 1 0 1</ambient>
          <diffuse>0 1 0 1</diffuse>
          <specular>0 0 0 1</specular>
          <emissive>0 0 0 1</emissive>
        </material>
        <transparency>0</transparency>
        <cast_shadows>1</cast_shadows>
      </visual>
    </link>
    <joint name="x_rotation_kinematic_joint" type="revolute">
      <child>soccer_ball_link</child>
      <parent>y_rotation_kinematic_link</parent>
      <axis>
        <xyz>1 0 0</xyz>
        <dynamics>
          <friction>0.001</friction>
          <damping>0.0001</damping>
        </dynamics>
      </axis>
    </joint>
    <link name="y_rotation_kinematic_link">
      <gravity>false</gravity>
      <inertial>
        <mass>1e-5</mass>
        <inertia>
          <ixx>1e-5</ixx>
          <ixy>0</ixy>
          <ixz>0</ixz>
          <iyy>1e-5</iyy>
          <iyz>0</iyz>
          <izz>1e-5</izz>
        </inertia>
      </inertial>
    </link>
    <joint name="y_rotation_kinematic_joint" type="revolute">
      <child>y_rotation_kinematic_link</child>
      <parent>z_rotation_kinematic_link</parent>
      <axis>
        <xyz>0 1 0</xyz>
        <dynamics>
          <friction>0.001</friction>
          <damping>0.0001</damping>
        </dynamics>
      </axis>
    </joint>
    <link name="z_rotation_kinematic_link">
      <gravity>false</gravity>
      <inertial>
        <mass>1e-5</mass>
        <inertia>
          <ixx>1e-5</ixx>
          <ixy>0</ixy>
          <ixz>0</ixz>
          <iyy>1e-5</iyy>
          <iyz>0</iyz>
          <izz>1e-5</izz>
        </inertia>
      </inertial>
    </link>
    <joint name="z_rotation_kinematic_joint" type="revolute">
      <child>z_rotation_kinematic_link</child>
      <parent>z_direction_kinematic_link</parent>
      <axis>
        <xyz>0 0 1</xyz>
        <dynamics>
          <friction>0.001</friction>
          <damping>0.0001</damping>
        </dynamics>
      </axis>
    </joint>
    <link name="z_direction_kinematic_link">
      <gravity>false</gravity>
      <inertial>
        <mass>1e-5</mass>
        <inertia>
          <ixx>1e-5</ixx>
          <ixy>0</ixy>
          <ixz>0</ixz>
          <iyy>1e-5</iyy>
          <iyz>0</iyz>
          <izz>1e-5</izz>
        </inertia>
      </inertial>
    </link>
    <joint name="z_direction_kinematic_joint" type="prismatic">
      <child>z_direction_kinematic_link</child>
      <parent>y_direction_kinematic_link</parent>
      <axis>
        <xyz>0 0 1</xyz>
        <dynamics>
          <friction>0.0001</friction>
          <damping>0.00001</damping>
        </dynamics>
      </axis>
    </joint>
    <link name="y_direction_kinematic_link">
      <gravity>false</gravity>
      <inertial>
        <mass>1e-5</mass>
      </inertial>
    </link>
    <joint name="y_direction_kinematic_joint" type="prismatic">
      <child>y_direction_kinematic_link</child>
      <parent>x_direction_kinematic_link</parent>
      <axis>
        <xyz>0 1 0</xyz>
        <dynamics>
          <friction>1000.0001</friction>
          <damping>10.00001</damping>
        </dynamics>
      </axis>
    </joint>
    <link name="x_direction_kinematic_link">
      <gravity>false</gravity>
      <inertial>
        <mass>1e-5</mass>
      </inertial>
    </link>
    <joint name="x_direction_kinematic_joint" type="prismatic">
      <child>x_direction_kinematic_link</child>
      <parent>world</parent>
      <axis>
        <xyz>1 0 0</xyz>
        <dynamics>
          <friction>0.0001</friction>
          <damping>0.00001</damping>
        </dynamics>
      </axis>
    </joint>
  </model>
</sdf>
